Workbook

Sheet Summary
A1: Project Name/ Number
A2: Test Case Authorizing Date | C2: Application | F2: Authorizing Effort
F3: Execution Effort
A4: Plan Author
A5: Test Execution Date | C5: Version | F5: Environment
F6: Actual Time
A7: Test Executed By
A8: Test Status
A9: Scope
A10: Test Purpose or Objective
A11: Set Up Requirements or Considerations
A12: Notes or Special Instructions
A13: Database Changes
A14: Hardware or Network
A15: Items not included in test
A16: Assumptions
A18: Work Sheets in Test plan
A19: Defect List

Sheet Early Observations
A1: # | B1: Page | C1: Observation | D1: Why it matters | E1: Linked Test Case | F1: Status

Sheet Execution Plan
A1: Phase | B1: When | C1: Test Case Ids | D1: Dependency and notes | E1: Est. hours

Sheet Coverage
A1: Test Type | B1: Total | C1: Pass | D1: Fail | E1: Blocked | F1: Not Executed | G1: % Executed
A2: Accessibility | B2: =COUNTIF('Functional Testing'!$M$2:$M$2000,A2) | C2: =COUNTIFS('Functional Testing'!$M$2:$M$2000,$A2,'Functional Testing'!$L$2:$L$2000,"Pass") | D2: =COUNTIFS('Functional Testing'!$M$2:$M$2000,$A2,'Functional Testing'!$L$2:$L$2000,"Fail") | E2: =COUNTIFS('Functional Testing'!$M$2:$M$2000,$A2,'Functional Testing'!$L$2:$L$2000,"Blocked") | F2: =COUNTIFS('Functional Testing'!$M$2:$M$2000,$A2,'Functional Testing'!$L$2:$L$2000,"Not Executed") | G2: =IF(B2=0,0,(C2+D2+E2)/B2)
A3: Admin | B3: =COUNTIF('Functional Testing'!$M$2:$M$2000,A3) | C3: =COUNTIFS('Functional Testing'!$M$2:$M$2000,$A3,'Functional Testing'!$L$2:$L$2000,"Pass") | D3: =COUNTIFS('Functional Testing'!$M$2:$M$2000,$A3,'Functional Testing'!$L$2:$L$2000,"Fail") | E3: =COUNTIFS('Functional Testing'!$M$2:$M$2000,$A3,'Functional Testing'!$L$2:$L$2000,"Blocked") | F3: =COUNTIFS('Functional Testing'!$M$2:$M$2000,$A3,'Functional Testing'!$L$2:$L$2000,"Not Executed") | G3: =IF(B3=0,0,(C3+D3+E3)/B3)
A4: Boundary | B4: =COUNTIF('Functional Testing'!$M$2:$M$2000,A4) | C4: =COUNTIFS('Functional Testing'!$M$2:$M$2000,$A4,'Functional Testing'!$L$2:$L$2000,"Pass") | D4: =COUNTIFS('Functional Testing'!$M$2:$M$2000,$A4,'Functional Testing'!$L$2:$L$2000,"Fail") | E4: =COUNTIFS('Functional Testing'!$M$2:$M$2000,$A4,'Functional Testing'!$L$2:$L$2000,"Blocked") | F4: =COUNTIFS('Functional Testing'!$M$2:$M$2000,$A4,'Functional Testing'!$L$2:$L$2000,"Not Executed") | G4: =IF(B4=0,0,(C4+D4+E4)/B4)
A5: Compatibility | B5: =COUNTIF('Functional Testing'!$M$2:$M$2000,A5) | C5: =COUNTIFS('Functional Testing'!$M$2:$M$2000,$A5,'Functional Testing'!$L$2:$L$2000,"Pass") | D5: =COUNTIFS('Functional Testing'!$M$2:$M$2000,$A5,'Functional Testing'!$L$2:$L$2000,"Fail") | E5: =COUNTIFS('Functional Testing'!$M$2:$M$2000,$A5,'Functional Testing'!$L$2:$L$2000,"Blocked") | F5: =COUNTIFS('Functional Testing'!$M$2:$M$2000,$A5,'Functional Testing'!$L$2:$L$2000,"Not Executed") | G5: =IF(B5=0,0,(C5+D5+E5)/B5)
A6: Content | B6: =COUNTIF('Functional Testing'!$M$2:$M$2000,A6) | C6: =COUNTIFS('Functional Testing'!$M$2:$M$2000,$A6,'Functional Testing'!$L$2:$L$2000,"Pass") | D6: =COUNTIFS('Functional Testing'!$M$2:$M$2000,$A6,'Functional Testing'!$L$2:$L$2000,"Fail") | E6: =COUNTIFS('Functional Testing'!$M$2:$M$2000,$A6,'Functional Testing'!$L$2:$L$2000,"Blocked") | F6: =COUNTIFS('Functional Testing'!$M$2:$M$2000,$A6,'Functional Testing'!$L$2:$L$2000,"Not Executed") | G6: =IF(B6=0,0,(C6+D6+E6)/B6)
A7: Data Integrity | B7: =COUNTIF('Functional Testing'!$M$2:$M$2000,A7) | C7: =COUNTIFS('Functional Testing'!$M$2:$M$2000,$A7,'Functional Testing'!$L$2:$L$2000,"Pass") | D7: =COUNTIFS('Functional Testing'!$M$2:$M$2000,$A7,'Functional Testing'!$L$2:$L$2000,"Fail") | E7: =COUNTIFS('Functional Testing'!$M$2:$M$2000,$A7,'Functional Testing'!$L$2:$L$2000,"Blocked") | F7: =COUNTIFS('Functional Testing'!$M$2:$M$2000,$A7,'Functional Testing'!$L$2:$L$2000,"Not Executed") | G7: =IF(B7=0,0,(C7+D7+E7)/B7)
A8: Email | B8: =COUNTIF('Functional Testing'!$M$2:$M$2000,A8) | C8: =COUNTIFS('Functional Testing'!$M$2:$M$2000,$A8,'Functional Testing'!$L$2:$L$2000,"Pass") | D8: =COUNTIFS('Functional Testing'!$M$2:$M$2000,$A8,'Functional Testing'!$L$2:$L$2000,"Fail") | E8: =COUNTIFS('Functional Testing'!$M$2:$M$2000,$A8,'Functional Testing'!$L$2:$L$2000,"Blocked") | F8: =COUNTIFS('Functional Testing'!$M$2:$M$2000,$A8,'Functional Testing'!$L$2:$L$2000,"Not Executed") | G8: =IF(B8=0,0,(C8+D8+E8)/B8)
A9: End-to-End | B9: =COUNTIF('Functional Testing'!$M$2:$M$2000,A9) | C9: =COUNTIFS('Functional Testing'!$M$2:$M$2000,$A9,'Functional Testing'!$L$2:$L$2000,"Pass") | D9: =COUNTIFS('Functional Testing'!$M$2:$M$2000,$A9,'Functional Testing'!$L$2:$L$2000,"Fail") | E9: =COUNTIFS('Functional Testing'!$M$2:$M$2000,$A9,'Functional Testing'!$L$2:$L$2000,"Blocked") | F9: =COUNTIFS('Functional Testing'!$M$2:$M$2000,$A9,'Functional Testing'!$L$2:$L$2000,"Not Executed") | G9: =IF(B9=0,0,(C9+D9+E9)/B9)
A10: Error Handling | B10: =COUNTIF('Functional Testing'!$M$2:$M$2000,A10) | C10: =COUNTIFS('Functional Testing'!$M$2:$M$2000,$A10,'Functional Testing'!$L$2:$L$2000,"Pass") | D10: =COUNTIFS('Functional Testing'!$M$2:$M$2000,$A10,'Functional Testing'!$L$2:$L$2000,"Fail") | E10: =COUNTIFS('Functional Testing'!$M$2:$M$2000,$A10,'Functional Testing'!$L$2:$L$2000,"Blocked") | F10: =COUNTIFS('Functional Testing'!$M$2:$M$2000,$A10,'Functional Testing'!$L$2:$L$2000,"Not Executed") | G10: =IF(B10=0,0,(C10+D10+E10)/B10)
A11: Exploratory | B11: =COUNTIF('Functional Testing'!$M$2:$M$2000,A11) | C11: =COUNTIFS('Functional Testing'!$M$2:$M$2000,$A11,'Functional Testing'!$L$2:$L$2000,"Pass") | D11: =COUNTIFS('Functional Testing'!$M$2:$M$2000,$A11,'Functional Testing'!$L$2:$L$2000,"Fail") | E11: =COUNTIFS('Functional Testing'!$M$2:$M$2000,$A11,'Functional Testing'!$L$2:$L$2000,"Blocked") | F11: =COUNTIFS('Functional Testing'!$M$2:$M$2000,$A11,'Functional Testing'!$L$2:$L$2000,"Not Executed") | G11: =IF(B11=0,0,(C11+D11+E11)/B11)
A12: Functional | B12: =COUNTIF('Functional Testing'!$M$2:$M$2000,A12) | C12: =COUNTIFS('Functional Testing'!$M$2:$M$2000,$A12,'Functional Testing'!$L$2:$L$2000,"Pass") | D12: =COUNTIFS('Functional Testing'!$M$2:$M$2000,$A12,'Functional Testing'!$L$2:$L$2000,"Fail") | E12: =COUNTIFS('Functional Testing'!$M$2:$M$2000,$A12,'Functional Testing'!$L$2:$L$2000,"Blocked") | F12: =COUNTIFS('Functional Testing'!$M$2:$M$2000,$A12,'Functional Testing'!$L$2:$L$2000,"Not Executed") | G12: =IF(B12=0,0,(C12+D12+E12)/B12)
A13: Integration | B13: =COUNTIF('Functional Testing'!$M$2:$M$2000,A13) | C13: =COUNTIFS('Functional Testing'!$M$2:$M$2000,$A13,'Functional Testing'!$L$2:$L$2000,"Pass") | D13: =COUNTIFS('Functional Testing'!$M$2:$M$2000,$A13,'Functional Testing'!$L$2:$L$2000,"Fail") | E13: =COUNTIFS('Functional Testing'!$M$2:$M$2000,$A13,'Functional Testing'!$L$2:$L$2000,"Blocked") | F13: =COUNTIFS('Functional Testing'!$M$2:$M$2000,$A13,'Functional Testing'!$L$2:$L$2000,"Not Executed") | G13: =IF(B13=0,0,(C13+D13+E13)/B13)
... A23: Validation | B23: =COUNTIF('Functional Testing'!$M$2:$M$2000,A23) | C23: =COUNTIFS('Functional Testing'!$M$2:$M$2000,$A23,'Functional Testing'!$L$2:$L$2000,"Pass") | D23: =COUNTIFS('Functional Testing'!$M$2:$M$2000,$A23,'Functional Testing'!$L$2:$L$2000,"Fail") | E23: =COUNTIFS('Functional Testing'!$M$2:$M$2000,$A23,'Functional Testing'!$L$2:$L$2000,"Blocked") | F23: =COUNTIFS('Functional Testing'!$M$2:$M$2000,$A23,'Functional Testing'!$L$2:$L$2000,"Not Executed") | G23: =IF(B23=0,0,(C23+D23+E23)/B23)
A24: Total | B24: =SUM(B2:B23) | C24: =SUM(C2:C23) | D24: =SUM(D2:D23) | E24: =SUM(E2:E23) | F24: =SUM(F2:F23) | G24: =IF(B24=0,0,(C24+D24+E24)/B24)
A26: Priority summary
A27: Priority | B27: Total | C27: Pass | D27: Fail | E27: Blocked | F27: Not Executed | G27: % Executed
A28: High | B28: =COUNTIF('Functional Testing'!$K$2:$K$2000,A28) | C28: =COUNTIFS('Functional Testing'!$K$2:$K$2000,$A28,'Functional Testing'!$L$2:$L$2000,"Pass") | D28: =COUNTIFS('Functional Testing'!$K$2:$K$2000,$A28,'Functional Testing'!$L$2:$L$2000,"Fail") | E28: =COUNTIFS('Functional Testing'!$K$2:$K$2000,$A28,'Functional Testing'!$L$2:$L$2000,"Blocked") | F28: =COUNTIFS('Functional Testing'!$K$2:$K$2000,$A28,'Functional Testing'!$L$2:$L$2000,"Not Executed") | G28: =IF(B28=0,0,(C28+D28+E28)/B28)
A29: Medium | B29: =COUNTIF('Functional Testing'!$K$2:$K$2000,A29) | C29: =COUNTIFS('Functional Testing'!$K$2:$K$2000,$A29,'Functional Testing'!$L$2:$L$2000,"Pass") | D29: =COUNTIFS('Functional Testing'!$K$2:$K$2000,$A29,'Functional Testing'!$L$2:$L$2000,"Fail") | E29: =COUNTIFS('Functional Testing'!$K$2:$K$2000,$A29,'Functional Testing'!$L$2:$L$2000,"Blocked") | F29: =COUNTIFS('Functional Testing'!$K$2:$K$2000,$A29,'Functional Testing'!$L$2:$L$2000,"Not Executed") | G29: =IF(B29=0,0,(C29+D29+E29)/B29)
A30: Low | B30: =COUNTIF('Functional Testing'!$K$2:$K$2000,A30) | C30: =COUNTIFS('Functional Testing'!$K$2:$K$2000,$A30,'Functional Testing'!$L$2:$L$2000,"Pass") | D30: =COUNTIFS('Functional Testing'!$K$2:$K$2000,$A30,'Functional Testing'!$L$2:$L$2000,"Fail") | E30: =COUNTIFS('Functional Testing'!$K$2:$K$2000,$A30,'Functional Testing'!$L$2:$L$2000,"Blocked") | F30: =COUNTIFS('Functional Testing'!$K$2:$K$2000,$A30,'Functional Testing'!$L$2:$L$2000,"Not Executed") | G30: =IF(B30=0,0,(C30+D30+E30)/B30)
A33: Not covered in this round
A34: Area | B34: Reason | C34: Suggested owner
C35: Developer
C36: Developer or security vendor
C37: Retest when live
C38: Retest when live
C39: Developer
C40: Developer
C41: Optional
C42: Optional
C43: Client or CA

Sheet Client Mapping
A1: Client Check | B1: Check | C1: Test Case Id | D1: Priority | E1: Status

Sheet Functional Testing
A1: Test Case Id | B1: Requirement # | C1: Test Scenario | D1: Test Cases | E1: Pre-condition | F1: Test Steps | G1: Step Description | H1: Test data | I1: Expected Results | J1: Actual Results | K1: Priority | L1: Status | M1: Test Type
A2: TC_Auth_ValidLogin_001 | B2: BR 1.1 | C2: Login | D2: Verify login with a valid username and password | E2: User is on the SauceDemo login page | F2: Step 01 | G2: User enters standard_user and secret_sauce | K2: High | L2: Not Executed | M2: Functional
F3: Step 02 | G3: User clicks Login | I3: AC-AUTH-01: User is redirected to the products page AC-AUTH-02: The products page shows the inventory list
F4: Step 03
F5: Step 04
A7: TC_Auth_InvalidPassword_001 | B7: BR 1.1 | C7: Login | D7: Verify login with a valid username and a wrong password | E7: User is on the SauceDemo login page | F7: Step 01 | G7: User enters standard_user and an incorrect password | K7: Medium | L7: Not Executed | M7: Negative
F8: Step 02 | G8: User clicks Login | I8: AC-AUTH-03: An error message states that username and password do not match any user AC-AUTH-04: The user stays on the login page
F9: Step 03
F10: Step 04
A12: TC_Auth_LockedOutUser_001 | B12: BR 1.1 | C12: Login | D12: Verify login with a locked out user | E12: User is on the SauceDemo login page | F12: Step 01 | G12: User enters locked_out_user and secret_sauce | K12: Medium | L12: Not Executed | M12: Negative
F13: Step 02 | G13: User clicks Login | I13: AC-AUTH-05: An error message states that the user has been locked out
F14: Step 03
F15: Step 04
A17: TC_Auth_EmptyCredentials_001 | B17: BR 1.1 | C17: Login | D17: Verify login with empty username and password | E17: User is on the SauceDemo login page | F17: Step 01 | G17: User leaves both fields empty | K17: Medium | L17: Not Executed | M17: Validation
F18: Step 02 | G18: User clicks Login | I18: AC-AUTH-06: An error message states that the username is required
F19: Step 03
F20: Step 04
A22: TC_Auth_EmptyPassword_001 | B22: BR 1.1 | C22: Login | D22: Verify login with a username and an empty password | E22: User is on the SauceDemo login page | F22: Step 01 | G22: User enters standard_user and leaves the password empty | K22: Medium | L22: Not Executed | M22: Validation
F23: Step 02 | G23: User clicks Login | I23: AC-AUTH-07: An error message states that the password is required
F24: Step 03
F25: Step 04
A27: TC_Auth_LogoutFromMenu_001 | B27: BR 1.2 | C27: Logout | D27: Verify logout using the side menu | E27: 1. User is logged in as standard_user 2. User is on the products page | F27: Step 01 | G27: User opens the menu | K27: Low | L27: Not Executed | M27: State and Session
F28: Step 02 | G28: User clicks Logout | I28: AC-AUTH-08: User is returned to the login page AC-AUTH-09: Opening the products page URL directly shows an access error instead of the inventory
F29: Step 03
F30: Step 04
A32: TC_Inventory_ProductsDisplayed_001 | B32: BR 2.1 | C32: Product listing | D32: Verify products page lists all products | E32: 1. User is logged in as standard_user 2. User is on the products page | F32: Step 01 | G32: User views the products page | I32: AC-INV-01: Six products are listed AC-INV-02: Each product shows an image, name, description, price and an Add to cart button | K32: Low | L32: Not Executed | M32: Content
F33: Step 02
F34: Step 03
F35: Step 04
A37: TC_Inventory_SortByName_001 | B37: BR 2.2 | C37: Product sorting | D37: Verify sort products by name | E37: 1. User is logged in as standard_user 2. User is on the products page | F37: Step 01 | G37: User selects Name (A to Z) | K37: Low | L37: Not Executed | M37: Functional
F38: Step 02 | G38: User selects Name (Z to A) | I38: AC-INV-03: Products are ordered alphabetically for A to Z AC-INV-04: Products are in reverse alphabetical order for Z to A
F39: Step 03
F40: Step 04
A42: TC_Inventory_SortByPrice_001 | B42: BR 2.2 | C42: Product sorting | D42: Verify sort products by price | E42: 1. User is logged in as standard_user 2. User is on the products page | F42: Step 01 | G42: User selects Price (low to high) | K42: Low | L42: Not Executed | M42: Functional
F43: Step 02 | G43: User selects Price (high to low) | I43: AC-INV-05: Products are ordered from the lowest to the highest price AC-INV-06: Products are ordered from the highest to the lowest price
F44: Step 03
F45: Step 04
A47: TC_Cart_AddToCart_001 | B47: BR 3.1 | C47: Cart items | D47: Verify add a product to the cart | E47: 1. User is logged in as standard_user 2. User is on the products page | F47: Step 01 | G47: User clicks Add to cart on a product | I47: AC-CART-01: The cart badge shows the number of items added AC-CART-02: The button on that product changes to Remove | K47: Low | L47: Not Executed | M47: Functional
F48: Step 02
F49: Step 03
...

Sheet Defects
A1: Defect Id | B1: Date | C1: Linked Test Case Id | D1: Summary | E1: Device | F1: Browser and Version | G1: Page URL | H1: Steps to Reproduce | I1: Actual Result | J1: Expected Result | K1: Severity | L1: Priority | M1: Status | N1: Screenshot or Video Link | O1: Reported By

Sheet Regression Testing
A1: Regression Id | B1: Linked Test Case Id | C1: Scenario | D1: Test Case | E1: Client Check | F1: Run 1 Status | G1: Run 2 Status | H1: Remarks
